Workbook

Sheet Sector
A1: Code | B1: Sector
A2: A | B2: Agriculture
A3: I | B3: Industry
A4: S | B4: Services

Sheet Section
A1: Code | B1: Title
A2: A | B2: Agriculture, Forestry and Fishing
A3: B | B3: Mining and Quarrying
A4: C | B4: Manufacturing
A5: D | B5: Electricity, Gas, Steam and Air Conditioning Supply
A6: E | B6: Water Supply; Sewerage, Waste Management and Remediation Activities
A7: F | B7: Construction
A8: G | B8: Wholesale and Retail Trade; Repair of Motor Vehicles and Motorcycles
A9: H | B9: Transportation and Storage
A10: I | B10: Accommodation and Food Service Activities
A11: J | B11: Information and Communication
A12: K | B12: Financial and Insurance Activities
... A22: U | B22: Activities of Extra-Territorial Organizations and Bodies

Sheet Division
A1: Code | B1: Division | C1: Section | D1: Sector
A2: 1 | B2: Crop And Animal Production, Hunting And Related Service Activities | C2: A | D2: A
A3: 2 | B3: Forestry And Logging | C3: A | D3: A
A4: 3 | B4: Fishing And Aquaculture | C4: A | D4: A
A5: 5 | B5: Mining Of Coal And Lignite | C5: B | D5: I
A6: 6 | B6: Extraction Of Crude Petroleum And Natural Gas | C6: B | D6: I
A7: 7 | B7: Mining Of Metal Ores | C7: B | D7: I
A8: 8 | B8: Other Mining And Quarrying | C8: B | D8: I
A9: 9 | B9: Mining Support Service Activities | C9: B | D9: I
A10: 10 | B10: Manufacture Of Food Products | C10: C | D10: I
A11: 11 | B11: Manufacture Of Beverages | C11: C | D11: I
A12: 12 | B12: Manufacture Of Tobacco Products | C12: C | D12: I
A13: 13 | B13: Manufacture Of Textiles | C13: C | D13: I
... A89: 99 | B89: Activities of Extra-Territorial Organizations and Bodies | C89: U | D89: S

Sheet Class
A1: Class | B1: 1994 Class | C1: Section
A2: 0111 | B2: 0174 | C2: A
A3: 0111 | B3: 0176 | C3: A
A4: 0111 | B4: 0164 | C4: A
A5: 0111 | B5: 0176 | C5: A
A6: 0112 | B6: 0111 | C6: A
A7: 0112 | B7: 0112 | C7: A
A8: 0112 | B8: 0112 | C8: A
A9: 0112 | B9: 0113 | C9: A
A10: 0113 | B10: 0120 | C10: A
A11: 0114 | B11: 0150 | C11: A
A12: 0115 | B12: 0193 | C12: A
... A851: 9909 | B851: 9900 | C851: U

Sheet psic_old
A1: Class | B1: Section
A2: 0174 | B2: A
A3: 0176 | B3: A
A4: 0164 | B4: A
A5: 0176 | B5: A
A6: 0111 | B6: A
A7: 0112 | B7: A
A8: 0112 | B8: A
A9: 0113 | B9: A
A10: 0120 | B10: A
A11: 0150 | B11: A
A12: 0193 | B12: A
... A851: 9900 | B851: U

Sheet psic_new
A1: Class | B1: Section
A2: 0111 | B2: A
A3: 0111 | B3: A
A4: 0111 | B4: A
A5: 0111 | B5: A
A6: 0112 | B6: A
A7: 0112 | B7: A
A8: 0112 | B8: A
A9: 0112 | B9: A
A10: 0113 | B10: A
A11: 0114 | B11: A
A12: 0115 | B12: A
... A851: 9909 | B851: U

Sheet GDP_PSIC
A1: Industry | B1: Class
A2: AFF | B2: A
A3: Industry
A4: A. Mining and Quarrying | B4: B
A5: B. Manufacturing | B5: C
A6: C. Electricity, Steam, Water and Waste Management | B6: D
A7: C. Electricity, Steam, Water and Waste Management | B7: E
A8: D. Construction | B8: F
A9: Services
A10: A. Wholesale and Retail Trade; Repair of Motor Vehicles and Motorcycles | B10: G
A11: B. Transportation and Storage | B11: H
A12: C. Accommodation and food service activities | B12: I
A13: D. Information and communication | B13: J
A14: E. Financial and Insurance Activities | B14: K
A15: F. Real Estate and Ownership of Dwellings | B15: L
A16: G. Professional and Business Services | B16: M
A17: G. Professional and Business Services | B17: N
A18: H. Public Administration and Defense; Compulsory Social Activities | B18: O
A19: I. Education | B19: P
A20: J. Human Health and Social Work Activities | B20: Q
A21: K. Other Services | B21: R
... A24: K. Other Services | B24: U

Sheet Sheet1
A1: Class | B1: Description | C1: 1994 Class | D1: Division | E1: 1994 Division | F1: Same | G1: Section | H1: 1994 Section | I1: Same
A2: 0111 | B2: Growing of cereals (except rice and corn), leguminous crops and oil seeds | C2: 0174 | D2: =LEFT(A2,2) -> 01 | E2: =LEFT(C2,2) -> 01 | F2: =IF(ISBLANK(D2),"",IF(ISBLANK(E2),"",AND(D2=E2))) -> TRUE | G2: =INDEX(Sheet2!$A$2:$A$89, MATCH(D2, Sheet2!$B$2:$B$89, 0)) -> A | H2: =INDEX(Sheet2!$A$2:$A$89, MATCH(E2, Sheet2!$B$2:$B$89, 0)) -> A | I2: =IF(ISBLANK(G2),"",IF(ISBLANK(H2),"",AND(G2=H2))) -> TRUE
A3: 0111 | B3: Growing of cereals (except rice and corn), leguminous crops and oil seeds | C3: 0176 | D3: =LEFT(A3,2) -> 01 | E3: =LEFT(C3,2) -> 01 | F3: =IF(ISBLANK(D3),"",IF(ISBLANK(E3),"",AND(D3=E3))) -> TRUE | G3: =INDEX(Sheet2!$A$2:$A$89, MATCH(D3, Sheet2!$B$2:$B$89, 0)) -> A | H3: =INDEX(Sheet2!$A$2:$A$89, MATCH(E3, Sheet2!$B$2:$B$89, 0)) -> A | I3: =IF(ISBLANK(G3),"",IF(ISBLANK(H3),"",AND(G3=H3))) -> TRUE
A4: 0111 | B4: Growing of cereals (except rice and corn), leguminous crops and oil seeds | C4: 0164 | D4: =LEFT(A4,2) -> 01 | E4: =LEFT(C4,2) -> 01 | F4: =IF(ISBLANK(D4),"",IF(ISBLANK(E4),"",AND(D4=E4))) -> TRUE | G4: =INDEX(Sheet2!$A$2:$A$89, MATCH(D4, Sheet2!$B$2:$B$89, 0)) -> A | H4: =INDEX(Sheet2!$A$2:$A$89, MATCH(E4, Sheet2!$B$2:$B$89, 0)) -> A | I4: =IF(ISBLANK(G4),"",IF(ISBLANK(H4),"",AND(G4=H4))) -> TRUE
A5: 0111 | B5: Growing of cereals (except rice and corn), leguminous crops and oil seeds | C5: 0176 | D5: =LEFT(A5,2) -> 01 | E5: =LEFT(C5,2) -> 01 | F5: =IF(ISBLANK(D5),"",IF(ISBLANK(E5),"",AND(D5=E5))) -> TRUE | G5: =INDEX(Sheet2!$A$2:$A$89, MATCH(D5, Sheet2!$B$2:$B$89, 0)) -> A | H5: =INDEX(Sheet2!$A$2:$A$89, MATCH(E5, Sheet2!$B$2:$B$89, 0)) -> A | I5: =IF(ISBLANK(G5),"",IF(ISBLANK(H5),"",AND(G5=H5))) -> TRUE
A6: 0112 | B6: Growing of paddy rice | C6: 0111 | D6: =LEFT(A6,2) -> 01 | E6: =LEFT(C6,2) -> 01 | F6: =IF(ISBLANK(D6),"",IF(ISBLANK(E6),"",AND(D6=E6))) -> TRUE | G6: =INDEX(Sheet2!$A$2:$A$89, MATCH(D6, Sheet2!$B$2:$B$89, 0)) -> A | H6: =INDEX(Sheet2!$A$2:$A$89, MATCH(E6, Sheet2!$B$2:$B$89, 0)) -> A | I6: =IF(ISBLANK(G6),"",IF(ISBLANK(H6),"",AND(G6=H6))) -> TRUE
A7: 0112 | B7: Growing of paddy rice | C7: 0112 | D7: =LEFT(A7,2) -> 01 | E7: =LEFT(C7,2) -> 01 | F7: =IF(ISBLANK(D7),"",IF(ISBLANK(E7),"",AND(D7=E7))) -> TRUE | G7: =INDEX(Sheet2!$A$2:$A$89, MATCH(D7, Sheet2!$B$2:$B$89, 0)) -> A | H7: =INDEX(Sheet2!$A$2:$A$89, MATCH(E7, Sheet2!$B$2:$B$89, 0)) -> A | I7: =IF(ISBLANK(G7),"",IF(ISBLANK(H7),"",AND(G7=H7))) -> TRUE
A8: 0112 | B8: Growing of paddy rice | C8: 0112 | D8: =LEFT(A8,2) -> 01 | E8: =LEFT(C8,2) -> 01 | F8: =IF(ISBLANK(D8),"",IF(ISBLANK(E8),"",AND(D8=E8))) -> TRUE | G8: =INDEX(Sheet2!$A$2:$A$89, MATCH(D8, Sheet2!$B$2:$B$89, 0)) -> A | H8: =INDEX(Sheet2!$A$2:$A$89, MATCH(E8, Sheet2!$B$2:$B$89, 0)) -> A | I8: =IF(ISBLANK(G8),"",IF(ISBLANK(H8),"",AND(G8=H8))) -> TRUE
A9: 0112 | B9: Growing of paddy rice | C9: 0113 | D9: =LEFT(A9,2) -> 01 | E9: =LEFT(C9,2) -> 01 | F9: =IF(ISBLANK(D9),"",IF(ISBLANK(E9),"",AND(D9=E9))) -> TRUE | G9: =INDEX(Sheet2!$A$2:$A$89, MATCH(D9, Sheet2!$B$2:$B$89, 0)) -> A | H9: =INDEX(Sheet2!$A$2:$A$89, MATCH(E9, Sheet2!$B$2:$B$89, 0)) -> A | I9: =IF(ISBLANK(G9),"",IF(ISBLANK(H9),"",AND(G9=H9))) -> TRUE
A10: 0113 | B10: Growing of corn,except young corn (vegetable) | C10: 0120 | D10: =LEFT(A10,2) -> 01 | E10: =LEFT(C10,2) -> 01 | F10: =IF(ISBLANK(D10),"",IF(ISBLANK(E10),"",AND(D10=E10))) -> TRUE | G10: =INDEX(Sheet2!$A$2:$A$89, MATCH(D10, Sheet2!$B$2:$B$89, 0)) -> A | H10: =INDEX(Sheet2!$A$2:$A$89, MATCH(E10, Sheet2!$B$2:$B$89, 0)) -> A | I10: =IF(ISBLANK(G10),"",IF(ISBLANK(H10),"",AND(G10=H10))) -> TRUE
A11: 0114 | B11: Growing of sugar cane including muscovado sugar-making in the farm | C11: 0150 | D11: =LEFT(A11,2) -> 01 | E11: =LEFT(C11,2) -> 01 | F11: =IF(ISBLANK(D11),"",IF(ISBLANK(E11),"",AND(D11=E11))) -> TRUE | G11: =INDEX(Sheet2!$A$2:$A$89, MATCH(D11, Sheet2!$B$2:$B$89, 0)) -> A | H11: =INDEX(Sheet2!$A$2:$A$89, MATCH(E11, Sheet2!$B$2:$B$89, 0)) -> A | I11: =IF(ISBLANK(G11),"",IF(ISBLANK(H11),"",AND(G11=H11))) -> TRUE
A12: 0115 | B12: Growing of tobacco | C12: 0193 | D12: =LEFT(A12,2) -> 01 | E12: =LEFT(C12,2) -> 01 | F12: =IF(ISBLANK(D12),"",IF(ISBLANK(E12),"",AND(D12=E12))) -> TRUE | G12: =INDEX(Sheet2!$A$2:$A$89, MATCH(D12, Sheet2!$B$2:$B$89, 0)) -> A | H12: =INDEX(Sheet2!$A$2:$A$89, MATCH(E12, Sheet2!$B$2:$B$89, 0)) -> A | I12: =IF(ISBLANK(G12),"",IF(ISBLANK(H12),"",AND(G12=H12))) -> TRUE
A13: 0116 | B13: Growing of fiber crops | C13: 0191 | D13: =LEFT(A13,2) -> 01 | E13: =LEFT(C13,2) -> 01 | F13: =IF(ISBLANK(D13),"",IF(ISBLANK(E13),"",AND(D13=E13))) -> TRUE | G13: =INDEX(Sheet2!$A$2:$A$89, MATCH(D13, Sheet2!$B$2:$B$89, 0)) -> A | H13: =INDEX(Sheet2!$A$2:$A$89, MATCH(E13, Sheet2!$B$2:$B$89, 0)) -> A | I13: =IF(ISBLANK(G13),"",IF(ISBLANK(H13),"",AND(G13=H13))) -> TRUE
... A65: 0149 | B65: Raising of other animals | C65: 0299 | D65: =LEFT(A65,2) -> 01 | E65: =LEFT(C65,2) -> 02 | F65: =IF(ISBLANK(D65),"",IF(ISBLANK(E65),"",AND(D65=E65))) -> FALSE | G65: =INDEX(Sheet2!$A$2:$A$89, MATCH(D65, Sheet2!$B$2:$B$89, 0)) -> A | H65: =INDEX(Sheet2!$A$2:$A$89, MATCH(E65, Sheet2!$B$2:$B$89, 0)) -> A | I65: =IF(ISBLANK(G65),"",IF(ISBLANK(H65),"",AND(G65=H65))) -> TRUE
A66: 0149 | B66: Raising of other animals | C66: 0430 | D66: =LEFT(A66,2) -> 01 | E66: =LEFT(C66,2) -> 04 | F66: =IF(ISBLANK(D66),"",IF(ISBLANK(E66),"",AND(D66=E66))) -> FALSE | G66: =INDEX(Sheet2!$A$2:$A$89, MATCH(D66, Sheet2!$B$2:$B$89, 0)) -> A | H66: A | I66: =IF(ISBLANK(G66),"",IF(ISBLANK(H66),"",AND(G66=H66))) -> TRUE
A67: 0151 | B67: Operation of irrigation systems through cooperatives and non-cooperatives | C67: 0311 | D67: =LEFT(A67,2) -> 01 | E67: =LEFT(C67,2) -> 03 | F67: =IF(ISBLANK(D67),"",IF(ISBLANK(E67),"",AND(D67=E67))) -> FALSE | G67: =INDEX(Sheet2!$A$2:$A$89, MATCH(D67, Sheet2!$B$2:$B$89, 0)) -> A | H67: =INDEX(Sheet2!$A$2:$A$89, MATCH(E67, Sheet2!$B$2:$B$89, 0)) -> A | I67: =IF(ISBLANK(G67),"",IF(ISBLANK(H67),"",AND(G67=H67))) -> TRUE
A68: 0151 | B68: Operation of irrigation systems through cooperatives and non-cooperatives | C68: 0312 | D68: =LEFT(A68,2) -> 01 | E68: =LEFT(C68,2) -> 03 | F68: =IF(ISBLANK(D68),"",IF(ISBLANK(E68),"",AND(D68=E68))) -> FALSE | G68: =INDEX(Sheet2!$A$2:$A$89, MATCH(D68, Sheet2!$B$2:$B$89, 0)) -> A | H68: =INDEX(Sheet2!$A$2:$A$89, MATCH(E68, Sheet2!$B$2:$B$89, 0)) -> A | I68: =IF(ISBLANK(G68),"",IF(ISBLANK(H68),"",AND(G68=H68))) -> TRUE
A69: 0152 | B69: Planting, transplanting and other related activities | C69: 0320 | D69: =LEFT(A69,2) -> 01 | E69: =LEFT(C69,2) -> 03 | F69: =IF(ISBLANK(D69),"",IF(ISBLANK(E69),"",AND(D69=E69))) -> FALSE | G69: =INDEX(Sheet2!$A$2:$A$89, MATCH(D69, Sheet2!$B$2:$B$89, 0)) -> A | H69: =INDEX(Sheet2!$A$2:$A$89, MATCH(E69, Sheet2!$B$2:$B$89, 0)) -> A | I69: =IF(ISBLANK(G69),"",IF(ISBLANK(H69),"",AND(G69=H69))) -> TRUE
A70: 0153 | B70: Services to establish crops, promote their growth and protect them from pests and diseases | C70: 0331 | D70: =LEFT(A70,2) -> 01 | E70: =LEFT(C70,2) -> 03 | F70: =IF(ISBLANK(D70),"",IF(ISBLANK(E70),"",AND(D70=E70))) -> FALSE | G70: =INDEX(Sheet2!$A$2:$A$89, MATCH(D70, Sheet2!$B$2:$B$89, 0)) -> A | H70: =INDEX(Sheet2!$A$2:$A$89, MATCH(E70, Sheet2!$B$2:$B$89, 0)) -> A | I70: =IF(ISBLANK(G70),"",IF(ISBLANK(H70),"",AND(G70=H70))) -> TRUE
A71: 0153 | B71: Services to establish crops, promote their growth and protect them from pests and diseases | C71: 0332 | D71: =LEFT(A71,2) -> 01 | E71: =LEFT(C71,2) -> 03 | F71: =IF(ISBLANK(D71),"",IF(ISBLANK(E71),"",AND(D71=E71))) -> FALSE | G71: =INDEX(Sheet2!$A$2:$A$89, MATCH(D71, Sheet2!$B$2:$B$89, 0)) -> A | H71: =INDEX(Sheet2!$A$2:$A$89, MATCH(E71, Sheet2!$B$2:$B$89, 0)) -> A | I71: =IF(ISBLANK(G71),"",IF(ISBLANK(H71),"",AND(G71=H71))) -> TRUE
A72: 0153 | B72: Services to establish crops, promote their growth and protect them from pests and diseases | C72: 0333 | D72: =LEFT(A72,2) -> 01 | E72: =LEFT(C72,2) -> 03 | F72: =IF(ISBLANK(D72),"",IF(ISBLANK(E72),"",AND(D72=E72))) -> FALSE | G72: =INDEX(Sheet2!$A$2:$A$89, MATCH(D72, Sheet2!$B$2:$B$89, 0)) -> A | H72: =INDEX(Sheet2!$A$2:$A$89, MATCH(E72, Sheet2!$B$2:$B$89, 0)) -> A | I72: =IF(ISBLANK(G72),"",IF(ISBLANK(H72),"",AND(G72=H72))) -> TRUE
A73: 0153 | B73: Services to establish crops, promote their growth and protect them from pests and diseases | C73: 0339 | D73: =LEFT(A73,2) -> 01 | E73: =LEFT(C73,2) -> 03 | F73: =IF(ISBLANK(D73),"",IF(ISBLANK(E73),"",AND(D73=E73))) -> FALSE | G73: =INDEX(Sheet2!$A$2:$A$89, MATCH(D73, Sheet2!$B$2:$B$89, 0)) -> A | H73: =INDEX(Sheet2!$A$2:$A$89, MATCH(E73, Sheet2!$B$2:$B$89, 0)) -> A | I73: =IF(ISBLANK(G73),"",IF(ISBLANK(H73),"",AND(G73=H73))) -> TRUE
A74: 0154 | B74: Harvesting, threshing, grading, bailing and related services | C74: 0340 | D74: =LEFT(A74,2) -> 01 | E74: =LEFT(C74,2) -> 03 | F74: =IF(ISBLANK(D74),"",IF(ISBLANK(E74),"",AND(D74=E74))) -> FALSE | G74: =INDEX(Sheet2!$A$2:$A$89, MATCH(D74, Sheet2!$B$2:$B$89, 0)) -> A | H74: =INDEX(Sheet2!$A$2:$A$89, MATCH(E74, Sheet2!$B$2:$B$89, 0)) -> A | I74: =IF(ISBLANK(G74),"",IF(ISBLANK(H74),"",AND(G74=H74))) -> TRUE
A75: 0155 | B75: Rental of farm machinery with drivers and crew | C75: 0350 | D75: =LEFT(A75,2) -> 01 | E75: =LEFT(C75,2) -> 03 | F75: =IF(ISBLANK(D75),"",IF(ISBLANK(E75),"",AND(D75=E75))) -> FALSE | G75: =INDEX(Sheet2!$A$2:$A$89, MATCH(D75, Sheet2!$B$2:$B$89, 0)) -> A | H75: =INDEX(Sheet2!$A$2:$A$89, MATCH(E75, Sheet2!$B$2:$B$89, 0)) -> A | I75: =IF(ISBLANK(G75),"",IF(ISBLANK(H75),"",AND(G75=H75))) -> TRUE
A76: 0156 | B76: Support activities for animal production | C76: 0371 | D76: =LEFT(A76,2) -> 01 | E76: =LEFT(C76,2) -> 03 | F76: =IF(ISBLANK(D76),"",IF(ISBLANK(E76),"",AND(D76=E76))) -> FALSE | G76: =INDEX(Sheet2!$A$2:$A$89, MATCH(D76, Sheet2!$B$2:$B$89, 0)) -> A | H76: =INDEX(Sheet2!$A$2:$A$89, MATCH(E76, Sheet2!$B$2:$B$89, 0)) -> A | I76: =IF(ISBLANK(G76),"",IF(ISBLANK(H76),"",AND(G76=H76))) -> TRUE
A77: 0156 | B77: Support activities for animal production | C77: 0372 | D77: =LEFT(A77,2) -> 01 | E77: =LEFT(C77,2) -> 03 | F77: =IF(ISBLANK(D77),"",IF(ISBLANK(E77),"",AND(D77=E77))) -> FALSE | G77: =INDEX(Sheet2!$A$2:$A$89, MATCH(D77, Sheet2!$B$2:$B$89, 0)) -> A | H77: =INDEX(Sheet2!$A$2:$A$89, MATCH(E77, Sheet2!$B$2:$B$89, 0)) -> A | I77: =IF(ISBLANK(G77),"",IF(ISBLANK(H77),"",AND(G77=H77))) -> TRUE
A78: 0156 | B78: Support activities for animal production | C78: 0373 | D78: =LEFT(A78,2) -> 01 | E78: =LEFT(C78,2) -> 03 | F78: =IF(ISBLANK(D78),"",IF(ISBLANK(E78),"",AND(D78=E78))) -> FALSE | G78: =INDEX(Sheet2!$A$2:$A$89, MATCH(D78, Sheet2!$B$2:$B$89, 0)) -> A | H78: =INDEX(Sheet2!$A$2:$A$89, MATCH(E78, Sheet2!$B$2:$B$89, 0)) -> A | I78: =IF(ISBLANK(G78),"",IF(ISBLANK(H78),"",AND(G78=H78))) -> TRUE
... A84: 0158 | B84: Seed processing for propagation | C84: 0178 | D84: =LEFT(A84,2) -> 01 | E84: =LEFT(C84,2) -> 01 | F84: =IF(ISBLANK(D84),"",IF(ISBLANK(E84),"",AND(D84=E84))) -> TRUE | G84: =INDEX(Sheet2!$A$2:$A$89, MATCH(D84, Sheet2!$B$2:$B$89, 0)) -> A | H84: =INDEX(Sheet2!$A$2:$A$89, MATCH(E84, Sheet2!$B$2:$B$89, 0)) -> A | I84: =IF(ISBLANK(G84),"",IF(ISBLANK(H84),"",AND(G84=H84))) -> TRUE
A85: 0170 | B85: Hunting, trapping and related service activities | C85: 0410 | D85: =LEFT(A85,2) -> 01 | E85: =LEFT(C85,2) -> 04 | F85: =IF(ISBLANK(D85),"",IF(ISBLANK(E85),"",AND(D85=E85))) -> FALSE | G85: =INDEX(Sheet2!$A$2:$A$89, MATCH(D85, Sheet2!$B$2:$B$89, 0)) -> A | H85: A | I85: =IF(ISBLANK(G85),"",IF(ISBLANK(H85),"",AND(G85=H85))) -> TRUE
A86: 0170 | B86: Hunting, trapping and related service activities | C86: 0420 | D86: =LEFT(A86,2) -> 01 | E86: =LEFT(C86,2) -> 04 | F86: =IF(ISBLANK(D86),"",IF(ISBLANK(E86),"",AND(D86=E86))) -> FALSE | G86: =INDEX(Sheet2!$A$2:$A$89, MATCH(D86, Sheet2!$B$2:$B$89, 0)) -> A | H86: A | I86: =IF(ISBLANK(G86),"",IF(ISBLANK(H86),"",AND(G86=H86))) -> TRUE
A87: 0170 | B87: Hunting, trapping and related service activities | C87: 0490 | D87: =LEFT(A87,2) -> 01 | E87: =LEFT(C87,2) -> 04 | F87: =IF(ISBLANK(D87),"",IF(ISBLANK(E87),"",AND(D87=E87))) -> FALSE | G87: =INDEX(Sheet2!$A$2:$A$89, MATCH(D87, Sheet2!$B$2:$B$89, 0)) -> A | H87: A | I87: =IF(ISBLANK(G87),"",IF(ISBLANK(H87),"",AND(G87=H87))) -> TRUE
A88: 0211 | B88: Growing of timber forest species (e.g. Gmelina, Eucalyptus, etc.), planting, replanting, transplanting, thinning and conserving of forest and timber tracts | C88: 0502 | D88: =LEFT(A88,2) -> 02 | E88: =LEFT(C88,2) -> 05 | F88: =IF(ISBLANK(D88),"",IF(ISBLANK(E88),"",AND(D88=E88))) -> FALSE | G88: =INDEX(Sheet2!$A$2:$A$89, MATCH(D88, Sheet2!$B$2:$B$89, 0)) -> A | H88: =INDEX(Sheet2!$A$2:$A$89, MATCH(E88, Sheet2!$B$2:$B$89, 0)) -> B | I88: =IF(ISBLANK(G88),"",IF(ISBLANK(H88),"",AND(G88=H88))) -> FALSE
A89: 0212 | B89: Operation of forest tree nurseries | C89: 0503 | D89: =LEFT(A89,2) -> 02 | E89: =LEFT(C89,2) -> 05 | F89: =IF(ISBLANK(D89),"",IF(ISBLANK(E89),"",AND(D89=E89))) -> FALSE | G89: =INDEX(Sheet2!$A$2:$A$89, MATCH(D89, Sheet2!$B$2:$B$89, 0)) -> A | H89: =INDEX(Sheet2!$A$2:$A$89, MATCH(E89, Sheet2!$B$2:$B$89, 0)) -> B | I89: =IF(ISBLANK(G89),"",IF(ISBLANK(H89),"",AND(G89=H89))) -> FALSE
A90: 0220 | B90: Logging | C90: 0501 | D90: =LEFT(A90,2) -> 02 | E90: =LEFT(C90,2) -> 05 | F90: =IF(ISBLANK(D90),"",IF(ISBLANK(E90),"",AND(D90=E90))) -> FALSE | G90: =INDEX(Sheet2!$A$2:$A$89, MATCH(D90, Sheet2!$B$2:$B$89, 0)) -> A | H90: =INDEX(Sheet2!$A$2:$A$89, MATCH(E90, Sheet2!$B$2:$B$89, 0)) -> B | I90: =IF(ISBLANK(G90),"",IF(ISBLANK(H90),"",AND(G90=H90))) -> FALSE
A91: 0220 | B91: Logging | C91: 0509 | D91: =LEFT(A91,2) -> 02 | E91: =LEFT(C91,2) -> 05 | F91: =IF(ISBLANK(D91),"",IF(ISBLANK(E91),"",AND(D91=E91))) -> FALSE | G91: =INDEX(Sheet2!$A$2:$A$89, MATCH(D91, Sheet2!$B$2:$B$89, 0)) -> A | H91: =INDEX(Sheet2!$A$2:$A$89, MATCH(E91, Sheet2!$B$2:$B$89, 0)) -> B | I91: =IF(ISBLANK(G91),"",IF(ISBLANK(H91),"",AND(G91=H91))) -> FALSE
A92: 0230 | B92: Gathering of non-wood forest products | C92: 0509 | D92: =LEFT(A92,2) -> 02 | E92: =LEFT(C92,2) -> 05 | F92: =IF(ISBLANK(D92),"",IF(ISBLANK(E92),"",AND(D92=E92))) -> FALSE | G92: =INDEX(Sheet2!$A$2:$A$89, MATCH(D92, Sheet2!$B$2:$B$89, 0)) -> A | H92: =INDEX(Sheet2!$A$2:$A$89, MATCH(E92, Sheet2!$B$2:$B$89, 0)) -> B | I92: =IF(ISBLANK(G92),"",IF(ISBLANK(H92),"",AND(G92=H92))) -> FALSE
A93: 0240 | B93: Support services to forestry | C93: 0509 | D93: =LEFT(A93,2) -> 02 | E93: =LEFT(C93,2) -> 05 | F93: =IF(ISBLANK(D93),"",IF(ISBLANK(E93),"",AND(D93=E93))) -> FALSE | G93: =INDEX(Sheet2!$A$2:$A$89, MATCH(D93, Sheet2!$B$2:$B$89, 0)) -> A | H93: =INDEX(Sheet2!$A$2:$A$89, MATCH(E93, Sheet2!$B$2:$B$89, 0)) -> B | I93: =IF(ISBLANK(G93),"",IF(ISBLANK(H93),"",AND(G93=H93))) -> FALSE
A94: 0311 | B94: Marine fishing | C94: 0611 | D94: =LEFT(A94,2) -> 03 | E94: =LEFT(C94,2) -> 06 | F94: =IF(ISBLANK(D94),"",IF(ISBLANK(E94),"",AND(D94=E94))) -> FALSE | G94: =INDEX(Sheet2!$A$2:$A$89, MATCH(D94, Sheet2!$B$2:$B$89, 0)) -> A | H94: =INDEX(Sheet2!$A$2:$A$89, MATCH(E94, Sheet2!$B$2:$B$89, 0)) -> B | I94: =IF(ISBLANK(G94),"",IF(ISBLANK(H94),"",AND(G94=H94))) -> FALSE
A95: 0311 | B95: Marine fishing | C95: 0612 | D95: =LEFT(A95,2) -> 03 | E95: =LEFT(C95,2) -> 06 | F95: =IF(ISBLANK(D95),"",IF(ISBLANK(E95),"",AND(D95=E95))) -> FALSE | G95: =INDEX(Sheet2!$A$2:$A$89, MATCH(D95, Sheet2!$B$2:$B$89, 0)) -> A | H95: =INDEX(Sheet2!$A$2:$A$89, MATCH(E95, Sheet2!$B$2:$B$89, 0)) -> B | I95: =IF(ISBLANK(G95),"",IF(ISBLANK(H95),"",AND(G95=H95))) -> FALSE
A96: 0311 | B96: Marine fishing | C96: 0613 | D96: =LEFT(A96,2) -> 03 | E96: =LEFT(C96,2) -> 06 | F96: =IF(ISBLANK(D96),"",IF(ISBLANK(E96),"",AND(D96=E96))) -> FALSE | G96: =INDEX(Sheet2!$A$2:$A$89, MATCH(D96, Sheet2!$B$2:$B$89, 0)) -> A | H96: =INDEX(Sheet2!$A$2:$A$89, MATCH(E96, Sheet2!$B$2:$B$89, 0)) -> B | I96: =IF(ISBLANK(G96),"",IF(ISBLANK(H96),"",AND(G96=H96))) -> FALSE
...

Sheet Sheet2
A1: Section | B1: Division
A2: A | B2: 01
A3: A | B3: 02
A4: A | B4: 03
A5: B | B5: 05
A6: B | B6: 06
A7: B | B7: 07
A8: B | B8: 08
A9: B | B9: 09
A10: C | B10: 10
A11: C | B11: 11
A12: C | B12: 12
A13: C | B13: 13
A14: C | B14: 14
A15: C | B15: 15
A16: C | B16: 16
A17: C | B17: 17
A18: C | B18: 18
A19: C | B19: 19
A20: C | B20: 20
A21: C | B21: 21
... A89: U | B89: 99

Sheet industries
A1: division_code | B1: division | E1: sector_id | F1: sector | G1: section_id | H1: section
A2: 1 | B2: Crop and Animal Production, Hunting and Related Service Activities | E2: A | F2: =IF(E2="A","Agriculture",IF(E2="I","Industry","Services")) -> Agriculture | G2: A | H2: =VLOOKUP(G2,Section!$A$2:$B$22,2) -> Agriculture, Forestry and Fishing
A3: 2 | B3: Forestry and Logging | E3: A | F3: =IF(E3="A","Agriculture",IF(E3="I","Industry","Services")) -> Agriculture | G3: A | H3: =VLOOKUP(G3,Section!$A$2:$B$22,2) -> Agriculture, Forestry and Fishing
A4: 3 | B4: Fishing and Aquaculture | E4: A | F4: =IF(E4="A","Agriculture",IF(E4="I","Industry","Services")) -> Agriculture | G4: A | H4: =VLOOKUP(G4,Section!$A$2:$B$22,2) -> Agriculture, Forestry and Fishing
A5: 5 | B5: Mining of Coal and Lignite | E5: I | F5: =IF(E5="A","Agriculture",IF(E5="I","Industry","Services")) -> Industry | G5: B | H5: =VLOOKUP(G5,Section!$A$2:$B$22,2) -> Mining and Quarrying
A6: 6 | B6: Extraction of Crude Petroleum and Natural Gas | E6: I | F6: =IF(E6="A","Agriculture",IF(E6="I","Industry","Services")) -> Industry | G6: B | H6: =VLOOKUP(G6,Section!$A$2:$B$22,2) -> Mining and Quarrying
A7: 7 | B7: Mining of Metal Ores | E7: I | F7: =IF(E7="A","Agriculture",IF(E7="I","Industry","Services")) -> Industry | G7: B | H7: =VLOOKUP(G7,Section!$A$2:$B$22,2) -> Mining and Quarrying
A8: 8 | B8: Other Mining and Quarrying | E8: I | F8: =IF(E8="A","Agriculture",IF(E8="I","Industry","Services")) -> Industry | G8: B | H8: =VLOOKUP(G8,Section!$A$2:$B$22,2) -> Mining and Quarrying
A9: 9 | B9: Mining Support Service Activities | E9: I | F9: =IF(E9="A","Agriculture",IF(E9="I","Industry","Services")) -> Industry | G9: B | H9: =VLOOKUP(G9,Section!$A$2:$B$22,2) -> Mining and Quarrying
A10: 10 | B10: Manufacture of Food Products | E10: I | F10: =IF(E10="A","Agriculture",IF(E10="I","Industry","Services")) -> Industry | G10: C | H10: =VLOOKUP(G10,Section!$A$2:$B$22,2) -> Manufacturing
A11: 11 | B11: Manufacture of Beverages | E11: I | F11: =IF(E11="A","Agriculture",IF(E11="I","Industry","Services")) -> Industry | G11: C | H11: =VLOOKUP(G11,Section!$A$2:$B$22,2) -> Manufacturing
A12: 12 | B12: Manufacture of Tobacco Products | E12: I | F12: =IF(E12="A","Agriculture",IF(E12="I","Industry","Services")) -> Industry | G12: C | H12: =VLOOKUP(G12,Section!$A$2:$B$22,2) -> Manufacturing
A13: 13 | B13: Manufacture of Textiles | E13: I | F13: =IF(E13="A","Agriculture",IF(E13="I","Industry","Services")) -> Industry | G13: C | H13: =VLOOKUP(G13,Section!$A$2:$B$22,2) -> Manufacturing
... A89: 99 | B89: Activities of Extra-Territorial Organizations and Bodies | E89: S | F89: =IF(E89="A","Agriculture",IF(E89="I","Industry","Services")) -> Services | G89: U | H89: =VLOOKUP(G89,Section!$A$2:$B$22,2) -> Activities of Extra-Territorial Organizations and Bodies

Sheet Sheet4
A1: sector_id | B1: sector | C1: section_id | D1: section | E1: division_code | F1: division
A2: A | B2: Agriculture | C2: A | D2: Agriculture, Forestry and Fishing | E2: 01 | F2: Crop and Animal Production, Hunting and Related Service Activities
A3: A | B3: Agriculture | C3: A | D3: Agriculture, Forestry and Fishing | E3: 02 | F3: Forestry and Logging
A4: A | B4: Agriculture | C4: A | D4: Agriculture, Forestry and Fishing | E4: 03 | F4: Fishing and Aquaculture
A5: I | B5: Industry | C5: B | D5: Mining and Quarrying | E5: 05 | F5: Mining of Coal and Lignite
A6: I | B6: Industry | C6: B | D6: Mining and Quarrying | E6: 06 | F6: Extraction of Crude Petroleum and Natural Gas
A7: I | B7: Industry | C7: B | D7: Mining and Quarrying | E7: 07 | F7: Mining of Metal Ores
A8: I | B8: Industry | C8: B | D8: Mining and Quarrying | E8: 08 | F8: Other Mining and Quarrying
A9: I | B9: Industry | C9: B | D9: Mining and Quarrying | E9: 09 | F9: Mining Support Service Activities
A10: I | B10: Industry | C10: C | D10: Manufacturing | E10: 10 | F10: Manufacture of Food Products
A11: I | B11: Industry | C11: C | D11: Manufacturing | E11: 11 | F11: Manufacture of Beverages
A12: I | B12: Industry | C12: C | D12: Manufacturing | E12: 12 | F12: Manufacture of Tobacco Products
A13: I | B13: Industry | C13: C | D13: Manufacturing | E13: 13 | F13: Manufacture of Textiles
A14: I | B14: Industry | C14: C | D14: Manufacturing | E14: 14 | F14: Manufacture of Wearing Apparel
A15: I | B15: Industry | C15: C | D15: Manufacturing | E15: 15 | F15: Manufacture of Leather and Related Products
A16: I | B16: Industry | C16: C | D16: Manufacturing | E16: 16 | F16: Manufacture of Wood and of Products of Wood and Cork, Except Furniture; Manufacture of Articles of Bamboo, Cane, Rattan and The Like; Manufacture of Articles of Straw and Plaiting Materials
A17: I | B17: Industry | C17: C | D17: Manufacturing | E17: 17 | F17: Manufacture of Paper and Paper Products
A18: I | B18: Industry | C18: C | D18: Manufacturing | E18: 18 | F18: Printing and Reproduction of Recorded Media
A19: I | B19: Industry | C19: C | D19: Manufacturing | E19: 19 | F19: Manufacture of Coke and Refined Petroleum Products
A20: I | B20: Industry | C20: C | D20: Manufacturing | E20: 20 | F20: Manufacture of Chemicals and Chemical Products
A21: I | B21: Industry | C21: C | D21: Manufacturing | E21: 21 | F21: Manufacture of Basic Pharmaceutical Products and Pharmaceutical Preparations
... A89: S | B89: Services | C89: U | D89: Activities of Extra-Territorial Organizations and Bodies | E89: 99 | F89: Activities of Extra-Territorial Organizations and Bodies
